<mujocoinclude>
  <body name='hook' pos='-0.4 0 2' euler='-1.57 0 0'>
    <inertial pos="0 0 0" mass="0.0927059" diaginertia="6.57134e-05 6.09611e-05 1.09932e-05" />
    <joint name='hook_x' type='slide' axis='1 0 0' range="-0.5   1.3"/>
    <joint name='hook_y' type='slide' axis='0 1 0' range="-0.9   0.7"/>
    <joint name='hook_z' type='slide' axis='0 0 1' range="-0.45 0.95"/>
    <geom type='cylinder' size='.02 .1' pos='0 0 0' contype="1" conaffinity="1"/>
    <geom type='cylinder' size='.02 .07' pos='.04 0 0.1' euler="0 1.57 0" contype="1" conaffinity="1"/>
    <geom type='cylinder' size='.02 .1' pos='.1 0 0.18' euler="0 0 0" contype="1" conaffinity="1"/>
    <geom type='cylinder' size='.01 .11' pos='-0.01 0 0.27' euler="0 1.57 0" contype="1" conaffinity="1"/>
    <geom type='sphere' size='.013' pos='-0.11 0 0.27' euler="0 1.57 0" contype="1" conaffinity="1"/>
    <site name='end_effector' pos='-0.01 0 0.27' size='0.01' euler='0 0 -0.785398'/>

      <!--visualize ef pos-->
    <!--<geom type='sphere' pos='-0.01 0 0.27' size='0.02' euler='0 0 -0.785398' rgba='1 0 0 1'/>-->
  </body>
</mujocoinclude>
